Workbook
Name Método_A: 'Auxiliares-D'!$U$4:$U$8
Name Método_A2: 'Auxiliares-D'!$V$4:$V$5
Name Método_B: 'Auxiliares-D'!$W$4:$W$16
Name Método_B2: 'Auxiliares-D'!$X$4:$X$12
Name Método_C: 'Auxiliares-D'!$Y$4:$Y$9
Name Método_D: 'Auxiliares-D'!$Z$4:$Z$6
Name Método_E: 'Auxiliares-D'!$AA$4:$AA$8
Name Método_F: 'Auxiliares-D'!$AB$4:$AB$7
Name Método_G: 'Auxiliares-D'!$AC$4:$AC$8

Sheet Dimensionamento
B2: Dimensionamento de Canalizações Elétricas
B5: Circuito | F5: Corrente de Serviço | K5: Balanço de potência | P5: Proteção | U5: Cabo | Y5: Metodo de referencia e modo de instalação | AB5: Correntes Admissiveis (Iz) | AO5: Verificação das condições proteção | AV5: Queda de tensão (pag.270)
B8: Origem | D8: Destino | F8: P (kW) | G8: cos φ | H8: S (kVA) | I8: Tensão (V) | J8: IB (A) | K8: Ku | L8: Ks | M8: Ke | N8: S' (kVA) | O8: I'B (A) | P8: Tipo | Q8: IN (A) | R8: IR / IN (Percentagem regulada) | S8: IR (A) (novo IN) | T8: I2 (A) | U8: L (m) | V8: Material | W8: Isolamento | X8: Referencia Cabo | Y8: Método Referencia (pag.250 - 255) | Z8: Ref. Modo de instalação (52H) | AA8: Quadro RTIEBT (pag. 378 - 392) | AB8: Nº Condutores Carregados | AC8: S (mm2) | AD8: IZ (A) | AE8: [F] Cabos Paralelos | AF8: [N] Cabos Paralelo | AG8: S (mm2) total [fases] | AH8: S (mm2) total [neutro] | AI8: IZ (A) Total | AJ8: Fator Correção | AN8: Iz' (A) | AO8: IB (A) | AP8: IN (A) | AQ8: Iz' (A) | AR8: IB<=IN<=Iz | AS8: I2 (A) | AT8: 1.45*Iz' (A) | AU8: I2 <= 1.45*Iz' | AV8: Tipo de instalação | AW8: Δumax (%) | AX8: cos Φ (default = 0,8) | AY8: sin Φ (default = 0,6) | AZ8: ρ (resistividade) [Ωmm2/m] | BA8: λ fase (reatancia linear) [Ω/m] (default = 0,00008) | BB8: u(V) | BC8: Δu(%) | BD8: Δu < Δumax | BE8: Δu(%) acumulado | BF8: Δu(%) acumulado < Δumax(%)
AJ9: Temperatura | AK9: Agrupamento de cabos | AL9: Resistividade térmica do solo | AM9: Enterrados e colocados dentro de tubos ou de travessias
B10: PT | D10: QGBT | F10: =H10*G10 -> 320 | G10: 0.8 | H10: 400 | I10: 400 | J10: =IF(I10 = 400,(H10*1000)/(SQRT(3)*400),(H10*1000)/(230)) -> 577.35027 | K10: 1 | L10: 1 | M10: 1 | N10: =H10*K10*L10*M10 -> 400 | O10: =IF(I10=400,(N10*1000)/(SQRT(3)*400),(N10*1000)/230) -> 577.35027 | P10: D | Q10: 630 | R10: 1 | S10: =Q10*R10 -> 630 | T10: {=IF(P10 ="D",1.45*S10,IF(P10 ="DR",1.3*S10,IF(E[](P10="F",S10<=4),2.1*S10,IF(E[](P10="F",E[](S10>4,S10<=16)),1.9*S10,IF(E[](P10="F",S10>16),1.6*S10)))))} -> 913.5 | U10: 3 | V10: Cu | W10: XLPE/EPR | X10: 2x (XV-5G120) | Y10: D | Z10: 61 | AA10: 52-C30 | AB10: 3 | AC10: 95 | AD10: 301 | AE10: 3 | AF10: 3 | AG10: =AC10*AE10 -> 285 | AH10: =AC10*AF10 -> 285 | AI10: =AD10*AE10 -> 903 | AJ10: 1 | AK10: 1 | AL10: 1 | AM10: 0.8 | AN10: =AI10*AJ10*AK10*AL10*AM10 -> 722.4 | AO10: =O10 -> 577.35027 | AP10: =S10 -> 630 | AQ10: =AN10 -> 722.4 | AR10: =IF(AND(AO10<=AP10, AP10<=AQ10), "ok", "nok") -> ok | AS10: =T10 -> 913.5 | AT10: =1.45*AQ10 -> 1047.48 | AU10: =IF(AS10<=AT10, "ok", "nok") -> ok | AV10: Instalação Baixa Tensão (outros usos) | AW10: =IF(AV10="Instalação Media Tensão (iluminação)",6, IF(AV10="Instalação Media Tensão (outros usos)",8, IF(AV10="Instalação Baixa Tensão (iluminação)",3, IF(AV10="Instalação Baixa Tensão (outros usos)",5, IF(AV10="Instalação coletiva - coluna",1, IF(AV10="Instalação coletiva - entrada",0.5, IF(AV10="Entrada individual - portinhola",1.5))))))) -> 5 | AX10: =G10 -> 0.8 | AY10: =SQRT(1-AX10^2) -> 0.6 | AZ10: =IF(V10="Cu",0.0225, IF(V10="Al",0.036,0)) -> 0.0225 | BA10: 8e-05 | BB10: =IF(I10=400, (AZ10*(U10/AG10)*AX10+BA10*U10*AY10)*AO10, 2*(AZ10*(U10/AG10)*AX10+BA10*U10*AY10)*AO10) -> 0.19253112 | BC10: =(BB10/230)*100 -> 0.083709183 | BD10: =IF(BC10<AW10,"ok","nok") -> ok | BE10: =BC10 -> 0.083709183 | BF10: =IF(BE10<AW10,"ok","nok") -> ok
B11: QGBT | D11: QE | F11: =H11*G11 -> 320 | G11: 0.8 | H11: 400 | I11: 400 | J11: =IF(I11 = 400,(H11*1000)/(SQRT(3)*400),(H11*1000)/(230)) -> 577.35027 | K11: 1 | L11: 0.8 | M11: 1 | N11: =H11*K11*L11*M11 -> 320 | O11: =IF(I11=400,(N11*1000)/(SQRT(3)*400),(N11*1000)/230) -> 461.88022 | P11: D | Q11: 500 | R11: 1 | S11: =Q11*R11 -> 500 | T11: {=IF(P11 ="D",1.45*S11,IF(P11 ="DR",1.3*S11,IF(E[](P11="F",S11<=4),2.1*S11,IF(E[](P11="F",E[](S11>4,S11<=16)),1.9*S11,IF(E[](P11="F",S11>16),1.6*S11)))))} -> 725 | U11: 27 | V11: Cu | W11: XLPE/EPR | X11: 2x (XV-5G70) | Y11: F | Z11: 13 | AA11: 52-C11 | AB11: 3 | AC11: 95 | AD11: 328 | AE11: 2 | AF11: 2 | AG11: =AC11*AE11 -> 190 | AH11: =AC11*AF11 -> 190 | AI11: =AD11*AE11 -> 656 | AJ11: 1 | AK11: 0.85 | AL11: 1 | AM11: 1 | AN11: =AI11*AJ11*AK11*AL11*AM11 -> 557.6 | AO11: =O11 -> 461.88022 | AP11: =S11 -> 500 | AQ11: =AN11 -> 557.6 | AR11: =IF(AND(AO11<=AP11, AP11<=AQ11), "ok", "nok") -> ok | AS11: =T11 -> 725 | AT11: =1.45*AQ11 -> 808.52 | AU11: =IF(AS11<=AT11, "ok", "nok") -> ok | AV11: Instalação Baixa Tensão (outros usos) | AW11: =IF(AV11="Instalação Media Tensão (iluminação)",6, IF(AV11="Instalação Media Tensão (outros usos)",8, IF(AV11="Instalação Baixa Tensão (iluminação)",3, IF(AV11="Instalação Baixa Tensão (outros usos)",5, IF(AV11="Instalação coletiva - coluna",1, IF(AV11="Instalação coletiva - entrada",0.5, IF(AV11="Entrada individual - portinhola",1.5))))))) -> 5 | AX11: =G11 -> 0.8 | AY11: =SQRT(1-AX11^2) -> 0.6 | AZ11: =IF(V11="Cu",0.0225, IF(V11="Al",0.036,0)) -> 0.0225 | BA11: 8e-05 | BB11: =IF(I11=400, (AZ11*(U11/AG11)*AX11+BA11*U11*AY11)*AO11, 2*(AZ11*(U11/AG11)*AX11+BA11*U11*AY11)*AO11) -> 1.7800377 | BC11: =(BB11/230)*100 -> 0.77392945 | BD11: =IF(BC11<AW11,"ok","nok") -> ok | BE11: =BC11+BE10 -> 0.85763863 | BF11: =IF(BE11<AW11,"ok","nok") -> ok
B12: QE | D12: QP-SA | F12: =H12*G12 -> 29.9 | G12: 0.8 | H12: =H21+H20+H19+H18+H17+H16 -> 37.375 | I12: 400 | J12: =IF(I12 = 400,(H12*1000)/(SQRT(3)*400),(H12*1000)/(230)) -> 53.946166 | K12: 1 | L12: 0.7 | M12: 1 | N12: =H12*M12*L12*K12 -> 26.1625 | O12: =IF(I12=400,(N12*1000)/(SQRT(3)*400),(N12*1000)/230) -> 37.762316 | P12: D | Q12: 40 | R12: 1 | S12: =Q12*R12 -> 40 | T12: =IF(P12 ="D",1.45*S12,IF(P12 ="DR",1.3*S12,IF(AND(P12="F",S12<=4),2.1*S12,IF(AND(P12="F",AND(S12>4,S12<=16)),1.9*S12,IF(AND(P12="F",S12>16),1.6*S12))))) -> 58 | U12: 11 | V12: Cu | W12: XLPE/EPR | X12: XV-5G4 | Y12: E | Z12: 13 | AA12: 52-C11 | AB12: 3 | AC12: 4 | AD12: 42 | AE12: 1 | AF12: 1 | AG12: =AC12*AE12 -> 4 | AH12: =AC12*AF12 -> 4 | AI12: =AD12*AE12 -> 42 | AJ12: 1 | AK12: 1 | AL12: 1 | AM12: 1 | AN12: =AI12*AJ12*AK12*AL12*AM12 -> 42 | AO12: =O12 -> 37.762316 | AP12: =Q12 -> 40 | AQ12: =AN12 -> 42 | AR12: =IF(AND(AO12<=AP12, AP12<=AQ12), "ok", "nok") -> ok | AS12: =T12 -> 58 | AT12: =1.45*AQ12 -> 60.9 | AU12: =IF(AS12<=AT12, "ok", "nok") -> ok | AV12: Instalação Baixa Tensão (outros usos) | AW12: =IF(AV12="Instalação Media Tensão (iluminação)",6, IF(AV12="Instalação Media Tensão (outros usos)",8, IF(AV12="Instalação Baixa Tensão (iluminação)",3, IF(AV12="Instalação Baixa Tensão (outros usos)",5, IF(AV12="Instalação coletiva - coluna",1, IF(AV12="Instalação coletiva - entrada",0.5, IF(AV12="Entrada individual - portinhola",1.5))))))) -> 5 | AX12: =G12 -> 0.8 | AY12: =SQRT(1-AX12^2) -> 0.6 | AZ12: =IF(V12="Cu",0.0225, IF(V12="Al",0.036,0)) -> 0.0225 | BA12: 8e-05 | BB12: =IF(I12=400, (AZ12*(U12/AG12)*AX12+BA12*U12*AY12)*AO12, 2*(AZ12*(U12/AG12)*AX12+BA12*U12*AY12)*AO12) -> 1.8891731 | BC12: =(BB12/230)*100 -> 0.82137963 | BD12: =IF(BC12<AW12,"ok","nok") -> ok | BE12: =BC12+BE11 -> 1.6790183 | BF12: =IF(BE12<AW12,"ok","nok") -> ok
B13: QE | D13: QP-AP1 | F13: =H13*G13 -> 68.773737 | G13: 0.8 | H13: =H24+H23+H22 -> 85.967172 | I13: 400 | J13: =IF(I13 = 400,(H13*1000)/(SQRT(3)*400),(H13*1000)/(230)) -> 124.08292 | K13: 1 | L13: 0.9 | M13: 1 | N13: =H13*K13*L13*M13 -> 77.370455 | O13: =IF(I13=400,(N13*1000)/(SQRT(3)*400),(N13*1000)/230) -> 111.67463 | P13: D | Q13: 125 | R13: 1 | S13: =Q13*R13 -> 125 | T13: =IF(P13 ="D",1.45*S13,IF(P13 ="DR",1.3*S13,IF(AND(P13="F",S13<=4),2.1*S13,IF(AND(P13="F",AND(S13>4,S13<=16)),1.9*S13,IF(AND(P13="F",S13>16),1.6*S13))))) -> 181.25 | U13: 21 | V13: Cu | W13: XLPE/EPR | X13: XV-5G25 | Y13: F | Z13: 13 | AA13: 52-C11 | AB13: 3 | AC13: 25 | AD13: 135 | AE13: 1 | AF13: 1 | AG13: =AC13*AE13 -> 25 | AH13: =AC13*AF13 -> 25 | AI13: =AD13*AE13 -> 135 | AJ13: 1 | AK13: 1 | AL13: 1 | AM13: 1 | AN13: =AI13*AJ13*AK13*AL13*AM13 -> 135 | AO13: =O13 -> 111.67463 | AP13: =Q13 -> 125 | AQ13: =AN13 -> 135 | AR13: =IF(AND(AO13<=AP13, AP13<=AQ13), "ok", "nok") -> ok | AS13: =T13 -> 181.25 | AT13: =1.45*AQ13 -> 195.75 | AU13: =IF(AS13<=AT13, "ok", "nok") -> ok | AV13: Instalação Baixa Tensão (outros usos) | AW13: =IF(AV13="Instalação Media Tensão (iluminação)",6, IF(AV13="Instalação Media Tensão (outros usos)",8, IF(AV13="Instalação Baixa Tensão (iluminação)",3, IF(AV13="Instalação Baixa Tensão (outros usos)",5, IF(AV13="Instalação coletiva - coluna",1, IF(AV13="Instalação coletiva - entrada",0.5, IF(AV13="Entrada individual - portinhola",1.5))))))) -> 5 | AX13: =G13 -> 0.8 | AY13: =SQRT(1-AX13^2) -> 0.6 | AZ13: =IF(V13="Cu",0.0225, IF(V13="Al",0.036,0)) -> 0.0225 | BA13: 8e-05 | BB13: =IF(I13=400, (AZ13*(U13/AG13)*AX13+BA13*U13*AY13)*AO13, 2*(AZ13*(U13/AG13)*AX13+BA13*U13*AY13)*AO13) -> 1.8010885 | BC13: =(BB13/230)*100 -> 0.78308194 | BD13: =IF(BC13<AW13,"ok","nok") -> ok | BE13: =BC13+BE11 -> 1.6407206 | BF13: =IF(BE13<AW13,"ok","nok") -> ok
B14: QE | D14: QP-AP2 | F14: =H14*G14 -> 52.595145 | G14: 0.8 | H14: =H34+H33+H32 -> 65.743931 | I14: 400 | J14: =IF(I14 = 400,(H14*1000)/(SQRT(3)*400),(H14*1000)/(230)) -> 94.893191 | K14: 1 | L14: 0.9 | M14: 1 | N14: =H14*L14*K14*M14 -> 59.169538 | O14: =IF(I14=400,(N14*1000)/(SQRT(3)*400),(N14*1000)/230) -> 85.403872 | P14: D | Q14: 100 | R14: 1 | S14: =Q14*R14 -> 100 | T14: =IF(P14 ="D",1.45*S14,IF(P14 ="DR",1.3*S14,IF(AND(P14="F",S14<=4),2.1*S14,IF(AND(P14="F",AND(S14>4,S14<=16)),1.9*S14,IF(AND(P14="F",S14>16),1.6*S14))))) -> 145 | U14: 26 | V14: Cu | W14: XLPE/EPR | X14: XV-5G16 | Y14: E | Z14: 13 | AA14: 52-C11 | AB14: 3 | AC14: 16 | AD14: 100 | AE14: 1 | AF14: 1 | AG14: =AC14*AE14 -> 16 | AH14: =AC14*AF14 -> 16 | AI14: =AD14*AE14 -> 100 | AJ14: 1 | AK14: 1 | AL14: 1 | AM14: 1 | AN14: =AI14*AJ14*AK14*AL14*AM14 -> 100 | AO14: =O14 -> 85.403872 | AP14: =Q14 -> 100 | AQ14: =AN14 -> 100 | AR14: =IF(AND(AO14<=AP14, AP14<=AQ14), "ok", "nok") -> ok | AS14: =T14 -> 145 | AT14: =1.45*AQ14 -> 145 | AU14: =IF(AS14<=AT14, "ok", "nok") -> ok | AV14: Instalação Baixa Tensão (outros usos) | AW14: =IF(AV14="Instalação Media Tensão (iluminação)",6, IF(AV14="Instalação Media Tensão (outros usos)",8, IF(AV14="Instalação Baixa Tensão (iluminação)",3, IF(AV14="Instalação Baixa Tensão (outros usos)",5, IF(AV14="Instalação coletiva - coluna",1, IF(AV14="Instalação coletiva - entrada",0.5, IF(AV14="Entrada individual - portinhola",1.5))))))) -> 5 | AX14: =G14 -> 0.8 | AY14: =SQRT(1-AX14^2) -> 0.6 | AZ14: =IF(V14="Cu",0.0225, IF(V14="Al",0.036,0)) -> 0.0225 | BA14: 8e-05 | BB14: =IF(I14=400, (AZ14*(U14/AG14)*AX14+BA14*U14*AY14)*AO14, 2*(AZ14*(U14/AG14)*AX14+BA14*U14*AY14)*AO14) -> 2.6046473 | BC14: =(BB14/230)*100 -> 1.1324553 | BD14: =IF(BC14<AW14,"ok","nok") -> ok | BE14: =BC14+BE11 -> 1.990094 | BF14: =IF(BE14<AW14,"ok","nok") -> ok
B15: QE | D15: QP-CD | F15: =H15*G15 -> 9.7 | G15: 0.8 | H15: =H41+H40 -> 12.125 | I15: 400 | J15: =IF(I15 = 400,(H15*1000)/(SQRT(3)*400),(H15*1000)/(230)) -> 17.50093 | K15: 1 | L15: 0.9 | M15: 1 | N15: =H15*L15*K15*M15 -> 10.9125 | O15: =IF(I15=400,(N15*1000)/(SQRT(3)*400),(N15*1000)/230) -> 15.750837 | P15: D | Q15: 16 | R15: 1 | S15: =Q15*R15 -> 16 | T15: =IF(P15 ="D",1.45*S15,IF(P15 ="DR",1.3*S15,IF(AND(P15="F",S15<=4),2.1*S15,IF(AND(P15="F",AND(S15>4,S15<=16)),1.9*S15,IF(AND(P15="F",S15>16),1.6*S15))))) -> 23.2 | U15: 12 | V15: Cu | W15: XLPE/EPR | X15: XV-5G4 | Y15: E | Z15: 13 | AA15: 52-C11 | AB15: 3 | AC15: 4 | AD15: 42 | AE15: 1 | AF15: 1 | AG15: =AC15*AE15 -> 4 | AH15: =AC15*AF15 -> 4 | AI15: =AD15*AE15 -> 42 | AJ15: 1 | AK15: 1 | AL15: 1 | AM15: 1 | AN15: =AI15*AJ15*AK15*AL15*AM15 -> 42 | AO15: =O15 -> 15.750837 | AP15: =Q15 -> 16 | AQ15: =AN15 -> 42 | AR15: =IF(AND(AO15<=AP15, AP15<=AQ15), "ok", "nok") -> ok | AS15: =T15 -> 23.2 | AT15: =1.45*AQ15 -> 60.9 | AU15: =IF(AS15<=AT15, "ok", "nok") -> ok | AV15: Instalação Baixa Tensão (outros usos) | AW15: =IF(AV15="Instalação Media Tensão (iluminação)",6, IF(AV15="Instalação Media Tensão (outros usos)",8, IF(AV15="Instalação Baixa Tensão (iluminação)",3, IF(AV15="Instalação Baixa Tensão (outros usos)",5, IF(AV15="Instalação coletiva - coluna",1, IF(AV15="Instalação coletiva - entrada",0.5, IF(AV15="Entrada individual - portinhola",1.5))))))) -> 5 | AX15: =G15 -> 0.8 | AY15: =SQRT(1-AX15^2) -> 0.6 | AZ15: =IF(V15="Cu",0.0225, IF(V15="Al",0.036,0)) -> 0.0225 | BA15: 8e-05 | BB15: =IF(I15=400, (AZ15*(U15/AG15)*AX15+BA15*U15*AY15)*AO15, 2*(AZ15*(U15/AG15)*AX15+BA15*U15*AY15)*AO15) -> 0.85961768 | BC15: =(BB15/230)*100 -> 0.37374682 | BD15: =IF(BC15<AW15,"ok","nok") -> ok | BE15: =BC15+BE11 -> 1.2313854 | BF15: =IF(BE15<AW15,"ok","nok") -> ok
B16: QP-SA | D16: QE-G | F16: 4.3 | G16: 0.8 | H16: =F16/G16 -> 5.375 | I16: 400 | J16: =IF(I16 = 400,(H16*1000)/(SQRT(3)*400),(H16*1000)/(230)) -> 7.7581442 | K16: 1 | L16: 1 | M16: 1 | N16: =H16*K16*L16*M16 -> 5.375 | O16: =IF(I16=400,(N16*1000)/(SQRT(3)*400),(N16*1000)/230) -> 7.7581442 | P16: D | Q16: 10 | R16: 1 | S16: =Q16*R16 -> 10 | T16: =IF(P16 ="D",1.45*S16,IF(P16 ="DR",1.3*S16,IF(AND(P16="F",S16<=4),2.1*S16,IF(AND(P16="F",AND(S16>4,S16<=16)),1.9*S16,IF(AND(P16="F",S16>16),1.6*S16))))) -> 14.5 | U16: 11 | V16: Cu | W16: XLPE/EPR | X16: XV-5G4 | Y16: C_ | Z16: 11 | AA16: 52-C4 | AB16: 3 | AC16: 4 | AD16: 40 | AE16: 1 | AF16: 1 | AG16: =AC16*AE16 -> 4 | AH16: =AC16*AF16 -> 4 | AI16: =AD16*AE16 -> 40 | AJ16: 1 | AK16: 1 | AL16: 1 | AM16: 1 | AN16: =AI16*AJ16*AK16*AL16*AM16 -> 40 | AO16: =O16 -> 7.7581442 | AP16: =Q16 -> 10 | AQ16: =AN16 -> 40 | AR16: =IF(AND(AO16<=AP16, AP16<=AQ16), "ok", "nok") -> ok | AS16: =T16 -> 14.5 | AT16: =1.45*AQ16 -> 58 | AU16: =IF(AS16<=AT16, "ok", "nok") -> ok | AV16: Instalação Baixa Tensão (outros usos) | AW16: =IF(AV16="Instalação Media Tensão (iluminação)",6, IF(AV16="Instalação Media Tensão (outros usos)",8, IF(AV16="Instalação Baixa Tensão (iluminação)",3, IF(AV16="Instalação Baixa Tensão (outros usos)",5, IF(AV16="Instalação coletiva - coluna",1, IF(AV16="Instalação coletiva - entrada",0.5, IF(AV16="Entrada individual - portinhola",1.5))))))) -> 5 | AX16: =G16 -> 0.8 | AY16: =SQRT(1-AX16^2) -> 0.6 | AZ16: =IF(V16="Cu",0.0225, IF(V16="Al",0.036,0)) -> 0.0225 | BA16: 8e-05 | BB16: =IF(I16=400, (AZ16*(U16/AG16)*AX16+BA16*U16*AY16)*AO16, 2*(AZ16*(U16/AG16)*AX16+BA16*U16*AY16)*AO16) -> 0.38812444 | BC16: =(BB16/230)*100 -> 0.16874976 | BD16: =IF(BC16<AW16,"ok","nok") -> ok | BE16: =BC16+$BE$12 -> 1.847768 | BF16: =IF(BE16<AW16,"ok","nok") -> ok
B17: QP-SA | D17: QE-A.AF | F17: 8.5 | G17: 0.8 | H17: =F17/G17 -> 10.625 | I17: 400 | J17: =IF(I17 = 400,(H17*1000)/(SQRT(3)*400),(H17*1000)/(230)) -> 15.335867 | K17: 1 | L17: 1 | M17: 1 | N17: =H17*K17*L17*M17 -> 10.625 | O17: =IF(I17=400,(N17*1000)/(SQRT(3)*400),(N17*1000)/230) -> 15.335867 | P17: D | Q17: 16 | R17: 1 | S17: =Q17*R17 -> 16 | T17: =IF(P17 ="D",1.45*S17,IF(P17 ="DR",1.3*S17,IF(AND(P17="F",S17<=4),2.1*S17,IF(AND(P17="F",AND(S17>4,S17<=16)),1.9*S17,IF(AND(P17="F",S17>16),1.6*S17))))) -> 23.2 | U17: 13 | V17: Cu | W17: XLPE/EPR | X17: XV-5G4 | Y17: C_ | Z17: 11 | AA17: 52-C4 | AB17: 3 | AC17: 4 | AD17: 40 | AE17: 1 | AF17: 1 | AG17: =AC17*AE17 -> 4 | AH17: =AC17*AF17 -> 4 | AI17: =AD17*AE17 -> 40 | AJ17: 1 | AK17: 1 | AL17: 1 | AM17: 1 | AN17: =AI17*AJ17*AK17*AL17*AM17 -> 40 | AO17: =O17 -> 15.335867 | AP17: =Q17 -> 16 | AQ17: =AN17 -> 40 | AR17: =IF(AND(AO17<=AP17, AP17<=AQ17), "ok", "nok") -> ok | AS17: =T17 -> 23.2 | AT17: =1.45*AQ17 -> 58 | AU17: =IF(AS17<=AT17, "ok", "nok") -> ok | AV17: Instalação Baixa Tensão (outros usos) | AW17: =IF(AV17="Instalação Media Tensão (iluminação)",6, IF(AV17="Instalação Media Tensão (outros usos)",8, IF(AV17="Instalação Baixa Tensão (iluminação)",3, IF(AV17="Instalação Baixa Tensão (outros usos)",5, IF(AV17="Instalação coletiva - coluna",1, IF(AV17="Instalação coletiva - entrada",0.5, IF(AV17="Entrada individual - portinhola",1.5))))))) -> 5 | AX17: =G17 -> 0.8 | AY17: =SQRT(1-AX17^2) -> 0.6 | AZ17: =IF(V17="Cu",0.0225, IF(V17="Al",0.036,0)) -> 0.0225 | BA17: 8e-05 | BB17: =IF(I17=400, (AZ17*(U17/AG17)*AX17+BA17*U17*AY17)*AO17, 2*(AZ17*(U17/AG17)*AX17+BA17*U17*AY17)*AO17) -> 0.90671777 | BC17: =(BB17/230)*100 -> 0.39422512 | BD17: =IF(BC17<AW17,"ok","nok") -> ok | BE17: =BC17+$BE$12 -> 2.0732434 | BF17: =IF(BE17<AW17,"ok","nok") -> ok
B18: QP-SA | D18: QE-S.R | F18: 3.2 | G18: 0.8 | H18: =F18/G18 -> 4 | I18: 400 | J18: =IF(I18 = 400,(H18*1000)/(SQRT(3)*400),(H18*1000)/(230)) -> 5.7735027 | K18: 1 | L18: 1 | M18: 1 | N18: =H18*K18*L18*M18 -> 4 | O18: =IF(I18=400,(N18*1000)/(SQRT(3)*400),(N18*1000)/230) -> 5.7735027 | P18: D | Q18: 6 | R18: 1 | S18: =Q18*R18 -> 6 | T18: =IF(P18 ="D",1.45*S18,IF(P18 ="DR",1.3*S18,IF(AND(P18="F",S18<=4),2.1*S18,IF(AND(P18="F",AND(S18>4,S18<=16)),1.9*S18,IF(AND(P18="F",S18>16),1.6*S18))))) -> 8.7 | U18: 20 | V18: Cu | W18: XLPE/EPR | X18: XV-5G4 | Y18: C_ | Z18: 11 | AA18: 52-C4 | AB18: 3 | AC18: 4 | AD18: 40 | AE18: 1 | AF18: 1 | AG18: =AC18*AE18 -> 4 | AH18: =AC18*AF18 -> 4 | AI18: =AD18*AE18 -> 40 | AJ18: 1 | AK18: 1 | AL18: 1 | AM18: 1 | AN18: =AI18*AJ18*AK18*AL18*AM18 -> 40 | AO18: =O18 -> 5.7735027 | AP18: =Q18 -> 6 | AQ18: =AN18 -> 40 | AR18: =IF(AND(AO18<=AP18, AP18<=AQ18), "ok", "nok") -> ok | AS18: =T18 -> 8.7 | AT18: =1.45*AQ18 -> 58 | AU18: =IF(AS18<=AT18, "ok", "nok") -> ok | AV18: Instalação Baixa Tensão (outros usos) | AW18: =IF(AV18="Instalação Media Tensão (iluminação)",6, IF(AV18="Instalação Media Tensão (outros usos)",8, IF(AV18="Instalação Baixa Tensão (iluminação)",3, IF(AV18="Instalação Baixa Tensão (outros usos)",5, IF(AV18="Instalação coletiva - coluna",1, IF(AV18="Instalação coletiva - entrada",0.5, IF(AV18="Entrada individual - portinhola",1.5))))))) -> 5 | AX18: =G18 -> 0.8 | AY18: =SQRT(1-AX18^2) -> 0.6 | AZ18: =IF(V18="Cu",0.0225, IF(V18="Al",0.036,0)) -> 0.0225 | BA18: 8e-05 | BB18: =IF(I18=400, (AZ18*(U18/AG18)*AX18+BA18*U18*AY18)*AO18, 2*(AZ18*(U18/AG18)*AX18+BA18*U18*AY18)*AO18) -> 0.5251578 | BC18: =(BB18/230)*100 -> 0.22832948 | BD18: =IF(BC18<AW18,"ok","nok") -> ok | BE18: =BC18+$BE$12 -> 1.9073477 | BF18: =IF(BE18<AW18,"ok","nok") -> ok
B19: QP-SA | D19: QE-AC | F19: 3.2 | G19: 0.8 | H19: =F19/G19 -> 4 | I19: 400 | J19: =IF(I19 = 400,(H19*1000)/(SQRT(3)*400),(H19*1000)/(230)) -> 5.7735027 | K19: 1 | L19: 1 | M19: 1 | N19: =H19*K19*L19*M19 -> 4 | O19: =IF(I19=400,(N19*1000)/(SQRT(3)*400),(N19*1000)/230) -> 5.7735027 | P19: D | Q19: 6 | R19: 1 | S19: =Q19*R19 -> 6 | T19: =IF(P19 ="D",1.45*S19,IF(P19 ="DR",1.3*S19,IF(AND(P19="F",S19<=4),2.1*S19,IF(AND(P19="F",AND(S19>4,S19<=16)),1.9*S19,IF(AND(P19="F",S19>16),1.6*S19))))) -> 8.7 | U19: 14 | V19: Cu | W19: XLPE/EPR | X19: XV-5G4 | Y19: C_ | Z19: 11 | AA19: 52-C4 | AB19: 3 | AC19: 4 | AD19: 40 | AE19: 1 | AF19: 1 | AG19: =AC19*AE19 -> 4 | AH19: =AC19*AF19 -> 4 | AI19: =AD19*AE19 -> 40 | AJ19: 1 | AK19: 1 | AL19: 1 | AM19: 1 | AN19: =AI19*AJ19*AK19*AL19*AM19 -> 40 | AO19: =O19 -> 5.7735027 | AP19: =Q19 -> 6 | AQ19: =AN19 -> 40 | AR19: =IF(AND(AO19<=AP19, AP19<=AQ19), "ok", "nok") -> ok | AS19: =T19 -> 8.7 | AT19: =1.45*AQ19 -> 58 | AU19: =IF(AS19<=AT19, "ok", "nok") -> ok | AV19: Instalação Baixa Tensão (outros usos) | AW19: =IF(AV19="Instalação Media Tensão (iluminação)",6, IF(AV19="Instalação Media Tensão (outros usos)",8, IF(AV19="Instalação Baixa Tensão (iluminação)",3, IF(AV19="Instalação Baixa Tensão (outros usos)",5, IF(AV19="Instalação coletiva - coluna",1, IF(AV19="Instalação coletiva - entrada",0.5, IF(AV19="Entrada individual - portinhola",1.5))))))) -> 5 | AX19: =G19 -> 0.8 | AY19: =SQRT(1-AX19^2) -> 0.6 | AZ19: =IF(V19="Cu",0.0225, IF(V19="Al",0.036,0)) -> 0.0225 | BA19: 8e-05 | BB19: =IF(I19=400, (AZ19*(U19/AG19)*AX19+BA19*U19*AY19)*AO19, 2*(AZ19*(U19/AG19)*AX19+BA19*U19*AY19)*AO19) -> 0.36761046 | BC19: =(BB19/230)*100 -> 0.15983064 | BD19: =IF(BC19<AW19,"ok","nok") -> ok | BE19: =BC19+$BE$12 -> 1.8388489 | BF19: =IF(BE19<AW19,"ok","nok") -> ok
B20: QP-SA | D20: QE-P | F20: 4.3 | G20: 0.8 | H20: =F20/G20 -> 5.375 | I20: 400 | J20: =IF(I20 = 400,(H20*1000)/(SQRT(3)*400),(H20*1000)/(230)) -> 7.7581442 | K20: 1 | L20: 1 | M20: 1 | N20: =H20*K20*L20*M20 -> 5.375 | O20: =IF(I20=400,(N20*1000)/(SQRT(3)*400),(N20*1000)/230) -> 7.7581442 | P20: D | Q20: 10 | R20: 1 | S20: =Q20*R20 -> 10 | T20: =IF(P20 ="D",1.45*S20,IF(P20 ="DR",1.3*S20,IF(AND(P20="F",S20<=4),2.1*S20,IF(AND(P20="F",AND(S20>4,S20<=16)),1.9*S20,IF(AND(P20="F",S20>16),1.6*S20))))) -> 14.5 | U20: 23 | V20: Cu | W20: XLPE/EPR | X20: XV-5G4 | Y20: C_ | Z20: 11 | AA20: 52-C4 | AB20: 3 | AC20: 4 | AD20: 40 | AE20: 1 | AF20: 1 | AG20: =AC20*AE20 -> 4 | AH20: =AC20*AF20 -> 4 | AI20: =AD20*AE20 -> 40 | AJ20: 1 | AK20: 1 | AL20: 1 | AM20: 1 | AN20: =AI20*AJ20*AK20*AL20*AM20 -> 40 | AO20: =O20 -> 7.7581442 | AP20: =Q20 -> 10 | AQ20: =AN20 -> 40 | AR20: =IF(AND(AO20<=AP20, AP20<=AQ20), "ok", "nok") -> ok | AS20: =T20 -> 14.5 | AT20: =1.45*AQ20 -> 58 | AU20: =IF(AS20<=AT20, "ok", "nok") -> ok | AV20: Instalação Baixa Tensão (outros usos) | AW20: =IF(AV20="Instalação Media Tensão (iluminação)",6, IF(AV20="Instalação Media Tensão (outros usos)",8, IF(AV20="Instalação Baixa Tensão (iluminação)",3, IF(AV20="Instalação Baixa Tensão (outros usos)",5, IF(AV20="Instalação coletiva - coluna",1, IF(AV20="Instalação coletiva - entrada",0.5, IF(AV20="Entrada individual - portinhola",1.5))))))) -> 5 | AX20: =G20 -> 0.8 | AY20: =SQRT(1-AX20^2) -> 0.6 | AZ20: =IF(V20="Cu",0.0225, IF(V20="Al",0.036,0)) -> 0.0225 | BA20: 8e-05 | BB20: =IF(I20=400, (AZ20*(U20/AG20)*AX20+BA20*U20*AY20)*AO20, 2*(AZ20*(U20/AG20)*AX20+BA20*U20*AY20)*AO20) -> 0.81153292 | BC20: =(BB20/230)*100 -> 0.3528404 | BD20: =IF(BC20<AW20,"ok","nok") -> ok | BE20: =BC20+$BE$12 -> 2.0318587 | BF20: =IF(BE20<AW20,"ok","nok") -> ok
B21: QP-SA | D21: QE-A.L | F21: 6.4 | G21: 0.8 | H21: =F21/G21 -> 8 | I21: 400 | J21: =IF(I21 = 400,(H21*1000)/(SQRT(3)*400),(H21*1000)/(230)) -> 11.547005 | K21: 1 | L21: 1 | M21: 1 | N21: =H21*K21*L21*M21 -> 8 | O21: =IF(I21=400,(N21*1000)/(SQRT(3)*400),(N21*1000)/230) -> 11.547005 | P21: D | Q21: 16 | R21: 1 | S21: =Q21*R21 -> 16 | T21: =IF(P21 ="D",1.45*S21,IF(P21 ="DR",1.3*S21,IF(AND(P21="F",S21<=4),2.1*S21,IF(AND(P21="F",AND(S21>4,S21<=16)),1.9*S21,IF(AND(P21="F",S21>16),1.6*S21))))) -> 23.2 | U21: 15 | V21: Cu | W21: XLPE/EPR | X21: XV-5G4 | Y21: C_ | Z21: 11 | AA21: 52-C4 | AB21: 3 | AC21: 4 | AD21: 40 | AE21: 1 | AF21: 1 | AG21: =AC21*AE21 -> 4 | AH21: =AC21*AF21 -> 4 | AI21: =AD21*AE21 -> 40 | AJ21: 1 | AK21: 1 | AL21: 1 | AM21: 1 | AN21: =AI21*AJ21*AK21*AL21*AM21 -> 40 | AO21: =O21 -> 11.547005 | AP21: =Q21 -> 16 | AQ21: =AN21 -> 40 | AR21: =IF(AND(AO21<=AP21, AP21<=AQ21), "ok", "nok") -> ok | AS21: =T21 -> 23.2 | AT21: =1.45*AQ21 -> 58 | AU21: =IF(AS21<=AT21, "ok", "nok") -> ok | AV21: Instalação Baixa Tensão (outros usos) | AW21: =IF(AV21="Instalação Media Tensão (iluminação)",6, IF(AV21="Instalação Media Tensão (outros usos)",8, IF(AV21="Instalação Baixa Tensão (iluminação)",3, IF(AV21="Instalação Baixa Tensão (outros usos)",5, IF(AV21="Instalação coletiva - coluna",1, IF(AV21="Instalação coletiva - entrada",0.5, IF(AV21="Entrada individual - portinhola",1.5))))))) -> 5 | AX21: =G21 -> 0.8 | AY21: =SQRT(1-AX21^2) -> 0.6 | AZ21: =IF(V21="Cu",0.0225, IF(V21="Al",0.036,0)) -> 0.0225 | BA21: 8e-05 | BB21: =IF(I21=400, (AZ21*(U21/AG21)*AX21+BA21*U21*AY21)*AO21, 2*(AZ21*(U21/AG21)*AX21+BA21*U21*AY21)*AO21) -> 0.78773671 | BC21: =(BB21/230)*100 -> 0.34249422 | BD21: =IF(BC21<AW21,"ok","nok") -> ok | BE21: =BC21+$BE$12 -> 2.0215125 | BF21: =IF(BE21<AW21,"ok","nok") -> ok
B22: QP-AP1 | D22: QE-PIN | F22: 12.2 | G22: 0.8 | H22: =F22/G22 -> 15.25 | I22: 400 | J22: =IF(I22 = 400,(H22*1000)/(SQRT(3)*400),(H22*1000)/(230)) -> 22.011479 | K22: 1 | L22: 1 | M22: 1 | N22: =H22*K22*L22*M22 -> 15.25 | O22: =IF(I22=400,(N22*1000)/(SQRT(3)*400),(N22*1000)/230) -> 22.011479 | P22: D | Q22: 25 | R22: 1 | S22: =Q22*R22 -> 25 | T22: =IF(P22 ="D",1.45*S22,IF(P22 ="DR",1.3*S22,IF(AND(P22="F",S22<=4),2.1*S22,IF(AND(P22="F",AND(S22>4,S22<=16)),1.9*S22,IF(AND(P22="F",S22>16),1.6*S22))))) -> 36.25 | U22: 50 | V22: Cu | W22: XLPE/EPR | X22: XV-5G4 | Y22: C_ | Z22: 11 | AA22: 52-C4 | AB22: 3 | AC22: 4 | AD22: 40 | AE22: 1 | AF22: 1 | AG22: =AC22*AE22 -> 4 | AH22: =AC22*AF22 -> 4 | AI22: =AD22*AE22 -> 40 | AJ22: 1 | AK22: 1 | AL22: 1 | AM22: 1 | AN22: =AI22*AJ22*AK22*AL22*AM22 -> 40 | AO22: =O22 -> 22.011479 | AP22: =Q22 -> 25 | AQ22: =AN22 -> 40 | AR22: =IF(AND(AO22<=AP22, AP22<=AQ22), "ok", "nok") -> ok | AS22: =T22 -> 36.25 | AT22: =1.45*AQ22 -> 58 | AU22: =IF(AS22<=AT22, "ok", "nok") -> ok | AV22: Instalação Baixa Tensão (outros usos) | AW22: =IF(AV22="Instalação Media Tensão (iluminação)",6, IF(AV22="Instalação Media Tensão (outros usos)",8, IF(AV22="Instalação Baixa Tensão (iluminação)",3, IF(AV22="Instalação Baixa Tensão (outros usos)",5, IF(AV22="Instalação coletiva - coluna",1, IF(AV22="Instalação coletiva - entrada",0.5, IF(AV22="Entrada individual - portinhola",1.5))))))) -> 5 | AX22: =G22 -> 0.8 | AY22: =SQRT(1-AX22^2) -> 0.6 | AZ22: =IF(V22="Cu",0.0225, IF(V22="Al",0.036,0)) -> 0.0225 | BA22: 8e-05 | BB22: =IF(I22=400, (AZ22*(U22/AG22)*AX22+BA22*U22*AY22)*AO22, 2*(AZ22*(U22/AG22)*AX22+BA22*U22*AY22)*AO22) -> 5.0054103 | BC22: =(BB22/230)*100 -> 2.1762654 | BD22: =IF(BC22<AW22,"ok","nok") -> ok | BE22: =BC22+$BE$13 -> 3.8169859 | BF22: =IF(BE22<AW22,"ok","nok") -> ok
B23: QP-AP1 | D23: QE-SEC | F23: 8.6 | G23: 0.8 | H23: =F23/G23 -> 10.75 | I23: 400 | J23: =IF(I23 = 400,(H23*1000)/(SQRT(3)*400),(H23*1000)/(230)) -> 15.516288 | K23: 1 | L23: 1 | M23: 1 | N23: =H23*K23*L23*M23 -> 10.75 | O23: =IF(I23=400,(N23*1000)/(SQRT(3)*400),(N23*1000)/230) -> 15.516288 | P23: D | Q23: 16 | R23: 1 | S23: =Q23*R23 -> 16 | T23: =IF(P23 ="D",1.45*S23,IF(P23 ="DR",1.3*S23,IF(AND(P23="F",S23<=4),2.1*S23,IF(AND(P23="F",AND(S23>4,S23<=16)),1.9*S23,IF(AND(P23="F",S23>16),1.6*S23))))) -> 23.2 | U23: 50 | V23: Cu | W23: XLPE/EPR | X23: XV-5G4 | Y23: C_ | Z23: 11 | AA23: 52-C4 | AB23: 3 | AC23: 4 | AD23: 40 | AE23: 1 | AF23: 1 | AG23: =AC23*AE23 -> 4 | AH23: =AC23*AF23 -> 4 | AI23: =AD23*AE23 -> 40 | AJ23: 1 | AK23: 1 | AL23: 1 | AM23: 1 | AN23: =AI23*AJ23*AK23*AL23*AM23 -> 40 | AO23: =O23 -> 15.516288 | AP23: =Q23 -> 16 | AQ23: =AN23 -> 40 | AR23: =IF(AND(AO23<=AP23, AP23<=AQ23), "ok", "nok") -> ok | AS23: =T23 -> 23.2 | AT23: =1.45*AQ23 -> 58 | AU23: =IF(AS23<=AT23, "ok", "nok") -> ok | AV23: Instalação Baixa Tensão (outros usos) | AW23: =IF(AV23="Instalação Media Tensão (iluminação)",6, IF(AV23="Instalação Media Tensão (outros usos)",8, IF(AV23="Instalação Baixa Tensão (iluminação)",3, IF(AV23="Instalação Baixa Tensão (outros usos)",5, IF(AV23="Instalação coletiva - coluna",1, IF(AV23="Instalação coletiva - entrada",0.5, IF(AV23="Entrada individual - portinhola",1.5))))))) -> 5 | AX23: =G23 -> 0.8 | AY23: =SQRT(1-AX23^2) -> 0.6 | AZ23: =IF(V23="Cu",0.0225, IF(V23="Al",0.036,0)) -> 0.0225 | BA23: 8e-05 | BB23: =IF(I23=400, (AZ23*(U23/AG23)*AX23+BA23*U23*AY23)*AO23, 2*(AZ23*(U23/AG23)*AX23+BA23*U23*AY23)*AO23) -> 3.528404 | BC23: =(BB23/230)*100 -> 1.5340887 | BD23: =IF(BC23<AW23,"ok","nok") -> ok | BE23: =BC23+$BE$13 -> 3.1748093 | BF23: =IF(BE23<AW23,"ok","nok") -> ok
B24: QP-AP1 | D24: QE-AP1 | F24: =H24*G24 -> 47.973737 | G24: 0.8 | H24: =H31+H30+H29+H28+H27+H26+H25 -> 59.967172 | I24: 400 | J24: =IF(I24 = 400,(H24*1000)/(SQRT(3)*400),(H24*1000)/(230)) -> 86.555157 | K24: 1 | L24: 0.7 | M24: 1 | N24: =H24*M24*L24*K24 -> 41.97702 | O24: =IF(I24=400,(N24*1000)/(SQRT(3)*400),(N24*1000)/230) -> 60.58861 | P24: D | Q24: 63 | R24: 1 | S24: =Q24*R24 -> 63 | T24: =IF(P24 ="D",1.45*S24,IF(P24 ="DR",1.3*S24,IF(AND(P24="F",S24<=4),2.1*S24,IF(AND(P24="F",AND(S24>4,S24<=16)),1.9*S24,IF(AND(P24="F",S24>16),1.6*S24))))) -> 91.35 | U24: 28 | V24: Cu | W24: XLPE/EPR | X24: XV-5G10 | Y24: E | Z24: 13 | AA24: 52-C11 | AB24: 3 | AC24: 10 | AD24: 75 | AE24: 1 | AF24: 1 | AG24: =AC24*AE24 -> 10 | AH24: =AC24*AF24 -> 10 | AI24: =AD24*AE24 -> 75 | AJ24: 1 | AK24: 1 | AL24: 1 | AM24: 1 | AN24: =AI24*AJ24*AK24*AL24*AM24 -> 75 | AO24: =O24 -> 60.58861 | AP24: =Q24 -> 63 | AQ24: =AN24 -> 75 | AR24: =IF(AND(AO24<=AP24, AP24<=AQ24), "ok", "nok") -> ok | AS24: =T24 -> 91.35 | AT24: =1.45*AQ24 -> 108.75 | AU24: =IF(AS24<=AT24, "ok", "nok") -> ok | AV24: Instalação Baixa Tensão (outros usos) | AW24: =IF(AV24="Instalação Media Tensão (iluminação)",6, IF(AV24="Instalação Media Tensão (outros usos)",8, IF(AV24="Instalação Baixa Tensão (iluminação)",3, IF(AV24="Instalação Baixa Tensão (outros usos)",5, IF(AV24="Instalação coletiva - coluna",1, IF(AV24="Instalação coletiva - entrada",0.5, IF(AV24="Entrada individual - portinhola",1.5))))))) -> 5 | AX24: =G24 -> 0.8 | AY24: =SQRT(1-AX24^2) -> 0.6 | AZ24: =IF(V24="Cu",0.0225, IF(V24="Al",0.036,0)) -> 0.0225 | BA24: 8e-05 | BB24: =IF(I24=400, (AZ24*(U24/AG24)*AX24+BA24*U24*AY24)*AO24, 2*(AZ24*(U24/AG24)*AX24+BA24*U24*AY24)*AO24) -> 3.135097 | BC24: =(BB24/230)*100 -> 1.3630857 | BD24: =IF(BC24<AW24,"ok","nok") -> ok | BE24: =BC24+$BE$13 -> 3.0038062 | BF24: =IF(BE24<AW24,"ok","nok") -> ok
B25: QE-AP1 | D25: QE-AVAC.1 | F25: 23.6 | G25: 0.8 | H25: =F25/G25 -> 29.5 | I25: 400 | J25: =IF(I25 = 400,(H25*1000)/(SQRT(3)*400),(H25*1000)/(230)) -> 42.579582 | K25: 1 | L25: 1 | M25: 1 | N25: =H25*K25*L25*M25 -> 29.5 | O25: =IF(I25=400,(N25*1000)/(SQRT(3)*400),(N25*1000)/230) -> 42.579582 | P25: D | Q25: 50 | R25: 1 | S25: =Q25*R25 -> 50 | T25: =IF(P25 ="D",1.45*S25,IF(P25 ="DR",1.3*S25,IF(AND(P25="F",S25<=4),2.1*S25,IF(AND(P25="F",AND(S25>4,S25<=16)),1.9*S25,IF(AND(P25="F",S25>16),1.6*S25))))) -> 72.5 | U25: 9 | V25: Cu | W25: XLPE/EPR | X25: XV-5G6 | Y25: E | Z25: 13 | AA25: 52-C11 | AB25: 3 | AC25: 6 | AD25: 54 | AE25: 1 | AF25: 1 | AG25: =AC25*AE25 -> 6 | AH25: =AC25*AF25 -> 6 | AI25: =AD25*AE25 -> 54 | AJ25: 1 | AK25: 1 | AL25: 1 | AM25: 1 | AN25: =AI25*AJ25*AK25*AL25*AM25 -> 54 | AO25: =O25 -> 42.579582 | AP25: =Q25 -> 50 | AQ25: =AN25 -> 54 | AR25: =IF(AND(AO25<=AP25, AP25<=AQ25), "ok", "nok") -> ok | AS25: =T25 -> 72.5 | AT25: =1.45*AQ25 -> 78.3 | AU25: =IF(AS25<=AT25, "ok", "nok") -> ok | AV25: Instalação Baixa Tensão (outros usos) | AW25: =IF(AV25="Instalação Media Tensão (iluminação)",6, IF(AV25="Instalação Media Tensão (outros usos)",8, IF(AV25="Instalação Baixa Tensão (iluminação)",3, IF(AV25="Instalação Baixa Tensão (outros usos)",5, IF(AV25="Instalação coletiva - coluna",1, IF(AV25="Instalação coletiva - entrada",0.5, IF(AV25="Entrada individual - portinhola",1.5))))))) -> 5 | AX25: =G25 -> 0.8 | AY25: =SQRT(1-AX25^2) -> 0.6 | AZ25: =IF(V25="Cu",0.0225, IF(V25="Al",0.036,0)) -> 0.0225 | BA25: 8e-05 | BB25: =IF(I25=400, (AZ25*(U25/AG25)*AX25+BA25*U25*AY25)*AO25, 2*(AZ25*(U25/AG25)*AX25+BA25*U25*AY25)*AO25) -> 1.1680431 | BC25: =(BB25/230)*100 -> 0.50784483 | BD25: =IF(BC25<AW25,"ok","nok") -> ok | BE25: =BC25+$BE$24 -> 3.5116511 | BF25: =IF(BE25<AW25,"ok","nok") -> ok
B26: QE-AP1 | D26: QE-M1 | F26: 3 | G26: 0.9 | H26: =F26/G26 -> 3.3333333 | I26: 400 | J26: =IF(I26 = 400,(H26*1000)/(SQRT(3)*400),(H26*1000)/(230)) -> 4.8112522 | K26: 1 | L26: 1 | M26: 1 | N26: =H26*K26*L26*M26 -> 3.3333333 | O26: =IF(I26=400,(N26*1000)/(SQRT(3)*400),(N26*1000)/230) -> 4.8112522 | P26: D | Q26: 6 | R26: 1 | S26: =Q26*R26 -> 6 | T26: =IF(P26 ="D",1.45*S26,IF(P26 ="DR",1.3*S26,IF(AND(P26="F",S26<=4),2.1*S26,IF(AND(P26="F",AND(S26>4,S26<=16)),1.9*S26,IF(AND(P26="F",S26>16),1.6*S26))))) -> 8.7 | U26: 23 | V26: Cu | W26: XLPE/EPR | X26: XV-5G4 | Y26: E | Z26: 13 | AA26: 52-C11 | AB26: 3 | AC26: 4 | AD26: 42 | AE26: 1 | AF26: 1 | AG26: =AC26*AE26 -> 4 | AH26: =AC26*AF26 -> 4 | AI26: =AD26*AE26 -> 42 | AJ26: 1 | AK26: 1 | AL26: 1 | AM26: 1 | AN26: =AI26*AJ26*AK26*AL26*AM26 -> 42 | AO26: =O26 -> 4.8112522 | AP26: =Q26 -> 6 | AQ26: =AN26 -> 42 | AR26: =IF(AND(AO26<=AP26, AP26<=AQ26), "ok", "nok") -> ok | AS26: =T26 -> 8.7 | AT26: =1.45*AQ26 -> 60.9 | AU26: =IF(AS26<=AT26, "ok", "nok") -> ok | AV26: Instalação Baixa Tensão (outros usos) | AW26: =IF(AV26="Instalação Media Tensão (iluminação)",6, IF(AV26="Instalação Media Tensão (outros usos)",8, IF(AV26="Instalação Baixa Tensão (iluminação)",3, IF(AV26="Instalação Baixa Tensão (outros usos)",5, IF(AV26="Instalação coletiva - coluna",1, IF(AV26="Instalação coletiva - entrada",0.5, IF(AV26="Entrada individual - portinhola",1.5))))))) -> 5 | AX26: =G26 -> 0.9 | AY26: =SQRT(1-AX26^2) -> 0.43588989 | AZ26: =IF(V26="Cu",0.0225, IF(V26="Al",0.036,0)) -> 0.0225 | BA26: 8e-05 | BB26: =IF(I26=400, (AZ26*(U26/AG26)*AX26+BA26*U26*AY26)*AO26, 2*(AZ26*(U26/AG26)*AX26+BA26*U26*AY26)*AO26) -> 0.56406899 | BC26: =(BB26/230)*100 -> 0.24524739 | BD26: =IF(BC26<AW26,"ok","nok") -> ok | BE26: =BC26+$BE$24 -> 3.2490536 | BF26: =IF(BE26<AW26,"ok","nok") -> ok
B27: QE-AP1 | D27: QE-M2 | F27: 1.5 | G27: 0.9 | H27: =F27/G27 -> 1.6666667 | I27: 400 | J27: =IF(I27 = 400,(H27*1000)/(SQRT(3)*400),(H27*1000)/(230)) -> 2.4056261 | K27: 1 | L27: 1 | M27: 1 | N27: =H27*K27*L27*M27 -> 1.6666667 | O27: =IF(I27=400,(N27*1000)/(SQRT(3)*400),(N27*1000)/230) -> 2.4056261 | P27: D | Q27: 6 | R27: 1 | S27: =Q27*R27 -> 6 | T27: =IF(P27 ="D",1.45*S27,IF(P27 ="DR",1.3*S27,IF(AND(P27="F",S27<=4),2.1*S27,IF(AND(P27="F",AND(S27>4,S27<=16)),1.9*S27,IF(AND(P27="F",S27>16),1.6*S27))))) -> 8.7 | U27: 27 | V27: Cu | W27: XLPE/EPR | X27: XV-5G4 | Y27: E | Z27: 13 | AA27: 52-C11 | AB27: 3 | AC27: 4 | AD27: 42 | AE27: 1 | AF27: 1 | AG27: =AC27*AE27 -> 4 | AH27: =AC27*AF27 -> 4 | AI27: =AD27*AE27 -> 42 | AJ27: 1 | AK27: 1 | AL27: 1 | AM27: 1 | AN27: =AI27*AJ27*AK27*AL27*AM27 -> 42 | AO27: =O27 -> 2.4056261 | AP27: =Q27 -> 6 | AQ27: =AN27 -> 42 | AR27: =IF(AND(AO27<=AP27, AP27<=AQ27), "ok", "nok") -> ok | AS27: =T27 -> 8.7 | AT27: =1.45*AQ27 -> 60.9 | AU27: =IF(AS27<=AT27, "ok", "nok") -> ok | AV27: Instalação Baixa Tensão (outros usos) | AW27: =IF(AV27="Instalação Media Tensão (iluminação)",6, IF(AV27="Instalação Media Tensão (outros usos)",8, IF(AV27="Instalação Baixa Tensão (iluminação)",3, IF(AV27="Instalação Baixa Tensão (outros usos)",5, IF(AV27="Instalação coletiva - coluna",1, IF(AV27="Instalação coletiva - entrada",0.5, IF(AV27="Entrada individual - portinhola",1.5))))))) -> 5 | AX27: =G27 -> 0.9 | AY27: =SQRT(1-AX27^2) -> 0.43588989 | AZ27: =IF(V27="Cu",0.0225, IF(V27="Al",0.036,0)) -> 0.0225 | BA27: 8e-05 | BB27: =IF(I27=400, (AZ27*(U27/AG27)*AX27+BA27*U27*AY27)*AO27, 2*(AZ27*(U27/AG27)*AX27+BA27*U27*AY27)*AO27) -> 0.33108397 | BC27: =(BB27/230)*100 -> 0.14394955 | BD27: =IF(BC27<AW27,"ok","nok") -> ok | BE27: =BC27+$BE$24 -> 3.1477558 | BF27: =IF(BE27<AW27,"ok","nok") -> ok
B28: QE-AP1 | D28: QE-M3 | F28: 5 | G28: 0.88 | H28: =F28/G28 -> 5.6818182 | I28: 400 | J28: =IF(I28 = 400,(H28*1000)/(SQRT(3)*400),(H28*1000)/(230)) -> 8.2009981 | K28: 1 | L28: 1 | M28: 1 | N28: =H28*K28*L28*M28 -> 5.6818182 | O28: =IF(I28=400,(N28*1000)/(SQRT(3)*400),(N28*1000)/230) -> 8.2009981 | P28: D | Q28: 10 | R28: 1 | S28: =Q28*R28 -> 10 | T28: =IF(P28 ="D",1.45*S28,IF(P28 ="DR",1.3*S28,IF(AND(P28="F",S28<=4),2.1*S28,IF(AND(P28="F",AND(S28>4,S28<=16)),1.9*S28,IF(AND(P28="F",S28>16),1.6*S28))))) -> 14.5 | U28: 22 | V28: Cu | W28: XLPE/EPR | X28: XV-5G4 | Y28: E | Z28: 13 | AA28: 52-C11 | AB28: 3 | AC28: 4 | AD28: 42 | AE28: 1 | AF28: 1 | AG28: =AC28*AE28 -> 4 | AH28: =AC28*AF28 -> 4 | AI28: =AD28*AE28 -> 42 | AJ28: 1 | AK28: 1 | AL28: 1 | AM28: 1 | AN28: =AI28*AJ28*AK28*AL28*AM28 -> 42 | AO28: =O28 -> 8.2009981 | AP28: =Q28 -> 10 | AQ28: =AN28 -> 42 | AR28: =IF(AND(AO28<=AP28, AP28<=AQ28), "ok", "nok") -> ok | AS28: =T28 -> 14.5 | AT28: =1.45*AQ28 -> 60.9 | AU28: =IF(AS28<=AT28, "ok", "nok") -> ok | AV28: Instalação Baixa Tensão (outros usos) | AW28: =IF(AV28="Instalação Media Tensão (iluminação)",6, IF(AV28="Instalação Media Tensão (outros usos)",8, IF(AV28="Instalação Baixa Tensão (iluminação)",3, IF(AV28="Instalação Baixa Tensão (outros usos)",5, IF(AV28="Instalação coletiva - coluna",1, IF(AV28="Instalação coletiva - entrada",0.5, IF(AV28="Entrada individual - portinhola",1.5))))))) -> 5 | AX28: =G28 -> 0.88 | AY28: =SQRT(1-AX28^2) -> 0.47497368 | AZ28: =IF(V28="Cu",0.0225, IF(V28="Al",0.036,0)) -> 0.0225 | BA28: 8e-05 | BB28: =IF(I28=400, (AZ28*(U28/AG28)*AX28+BA28*U28*AY28)*AO28, 2*(AZ28*(U28/AG28)*AX28+BA28*U28*AY28)*AO28) -> 0.89994435 | BC28: =(BB28/230)*100 -> 0.39128015 | BD28: =IF(BC28<AW28,"ok","nok") -> ok | BE28: =BC28+$BE$24 -> 3.3950864 | BF28: =IF(BE28<AW28,"ok","nok") -> ok
B29: QE-AP1 | D29: QE-M4 | F29: 4 | G29: 0.9 | H29: =F29/G29 -> 4.4444444 | I29: 400 | J29: =IF(I29 = 400,(H29*1000)/(SQRT(3)*400),(H29*1000)/(230)) -> 6.415003 | K29: 1 | L29: 1 | M29: 1 | N29: =H29*K29*L29*M29 -> 4.4444444 | O29: =IF(I29=400,(N29*1000)/(SQRT(3)*400),(N29*1000)/230) -> 6.415003 | P29: D | Q29: 10 | R29: 1 | S29: =Q29*R29 -> 10 | T29: =IF(P29 ="D",1.45*S29,IF(P29 ="DR",1.3*S29,IF(AND(P29="F",S29<=4),2.1*S29,IF(AND(P29="F",AND(S29>4,S29<=16)),1.9*S29,IF(AND(P29="F",S29>16),1.6*S29))))) -> 14.5 | U29: 21 | V29: Cu | W29: XLPE/EPR | X29: XV-5G4 | Y29: E | Z29: 13 | AA29: 52-C11 | AB29: 3 | AC29: 4 | AD29: 42 | AE29: 1 | AF29: 1 | AG29: =AC29*AE29 -> 4 | AH29: =AC29*AF29 -> 4 | AI29: =AD29*AE29 -> 42 | AJ29: 1 | AK29: 1 | AL29: 1 | AM29: 1 | AN29: =AI29*AJ29*AK29*AL29*AM29 -> 42 | AO29: =O29 -> 6.415003 | AP29: =Q29 -> 10 | AQ29: =AN29 -> 42 | AR29: =IF(AND(AO29<=AP29, AP29<=AQ29), "ok", "nok") -> ok | AS29: =T29 -> 14.5 | AT29: =1.45*AQ29 -> 60.9 | AU29: =IF(AS29<=AT29, "ok", "nok") -> ok | AV29: Instalação Baixa Tensão (outros usos) | AW29: =IF(AV29="Instalação Media Tensão (iluminação)",6, IF(AV29="Instalação Media Tensão (outros usos)",8, IF(AV29="Instalação Baixa Tensão (iluminação)",3, IF(AV29="Instalação Baixa Tensão (outros usos)",5, IF(AV29="Instalação coletiva - coluna",1, IF(AV29="Instalação coletiva - entrada",0.5, IF(AV29="Entrada individual - portinhola",1.5))))))) -> 5 | AX29: =G29 -> 0.9 | AY29: =SQRT(1-AX29^2) -> 0.43588989 | AZ29: =IF(V29="Cu",0.0225, IF(V29="Al",0.036,0)) -> 0.0225 | BA29: 8e-05 | BB29: =IF(I29=400, (AZ29*(U29/AG29)*AX29+BA29*U29*AY29)*AO29, 2*(AZ29*(U29/AG29)*AX29+BA29*U29*AY29)*AO29) -> 0.68669268 | BC29: =(BB29/230)*100 -> 0.29856203 | BD29: =IF(BC29<AW29,"ok","nok") -> ok | BE29: =BC29+$BE$24 -> 3.3023683 | BF29: =IF(BE29<AW29,"ok","nok") -> ok
B30: QE-AP1 | D30: QE-M5 | F30: 7.5 | G30: 0.88 | H30: =F30/G30 -> 8.5227273 | I30: 400 | J30: =IF(I30 = 400,(H30*1000)/(SQRT(3)*400),(H30*1000)/(230)) -> 12.301497 | K30: 1 | L30: 1 | M30: 1 | N30: =H30*K30*L30*M30 -> 8.5227273 | O30: =IF(I30=400,(N30*1000)/(SQRT(3)*400),(N30*1000)/230) -> 12.301497 | P30: D | Q30: 16 | R30: 1 | S30: =Q30*R30 -> 16 | T30: =IF(P30 ="D",1.45*S30,IF(P30 ="DR",1.3*S30,IF(AND(P30="F",S30<=4),2.1*S30,IF(AND(P30="F",AND(S30>4,S30<=16)),1.9*S30,IF(AND(P30="F",S30>16),1.6*S30))))) -> 23.2 | U30: 13 | V30: Cu | W30: XLPE/EPR | X30: XV-5G4 | Y30: E | Z30: 13 | AA30: 52-C11 | AB30: 3 | AC30: 4 | AD30: 42 | AE30: 1 | AF30: 1 | AG30: =AC30*AE30 -> 4 | AH30: =AC30*AF30 -> 4 | AI30: =AD30*AE30 -> 42 | AJ30: 1 | AK30: 1 | AL30: 1 | AM30: 1 | AN30: =AI30*AJ30*AK30*AL30*AM30 -> 42 | AO30: =O30 -> 12.301497 | AP30: =Q30 -> 16 | AQ30: =AN30 -> 42 | AR30: =IF(AND(AO30<=AP30, AP30<=AQ30), "ok", "nok") -> ok | AS30: =T30 -> 23.2 | AT30: =1.45*AQ30 -> 60.9 | AU30: =IF(AS30<=AT30, "ok", "nok") -> ok | AV30: Instalação Baixa Tensão (outros usos) | AW30: =IF(AV30="Instalação Media Tensão (iluminação)",6, IF(AV30="Instalação Media Tensão (outros usos)",8, IF(AV30="Instalação Baixa Tensão (iluminação)",3, IF(AV30="Instalação Baixa Tensão (outros usos)",5, IF(AV30="Instalação coletiva - coluna",1, IF(AV30="Instalação coletiva - entrada",0.5, IF(AV30="Entrada individual - portinhola",1.5))))))) -> 5 | AX30: =G30 -> 0.88 | AY30: =SQRT(1-AX30^2) -> 0.47497368 | AZ30: =IF(V30="Cu",0.0225, IF(V30="Al",0.036,0)) -> 0.0225 | BA30: 8e-05 | BB30: =IF(I30=400, (AZ30*(U30/AG30)*AX30+BA30*U30*AY30)*AO30, 2*(AZ30*(U30/AG30)*AX30+BA30*U30*AY30)*AO30) -> 0.79767795 | BC30: =(BB30/230)*100 -> 0.3468165 | BD30: =IF(BC30<AW30,"ok","nok") -> ok | BE30: =BC30+$BE$24 -> 3.3506227 | BF30: =IF(BE30<AW30,"ok","nok") -> ok
B31: QE-AP1 | D31: QE-M6 | F31: 6 | G31: 0.88 | H31: =F31/G31 -> 6.8181818 | I31: 400 | J31: =IF(I31 = 400,(H31*1000)/(SQRT(3)*400),(H31*1000)/(230)) -> 9.8411978 | K31: 1 | L31: 1 | M31: 1 | N31: =H31*K31*L31*M31 -> 6.8181818 | O31: =IF(I31=400,(N31*1000)/(SQRT(3)*400),(N31*1000)/230) -> 9.8411978 | P31: D | Q31: 10 | R31: 1 | S31: =Q31*R31 -> 10 | T31: =IF(P31 ="D",1.45*S31,IF(P31 ="DR",1.3*S31,IF(AND(P31="F",S31<=4),2.1*S31,IF(AND(P31="F",AND(S31>4,S31<=16)),1.9*S31,IF(AND(P31="F",S31>16),1.6*S31))))) -> 14.5 | U31: 15 | V31: Cu | W31: XLPE/EPR | X31: XV-5G4 | Y31: E | Z31: 13 | AA31: 52-C11 | AB31: 3 | AC31: 4 | AD31: 42 | AE31: 1 | AF31: 1 | AG31: =AC31*AE31 -> 4 | AH31: =AC31*AF31 -> 4 | AI31: =AD31*AE31 -> 42 | AJ31: 1 | AK31: 1 | AL31: 1 | AM31: 1 | AN31: =AI31*AJ31*AK31*AL31*AM31 -> 42 | AO31: =O31 -> 9.8411978 | AP31: =Q31 -> 10 | AQ31: =AN31 -> 42 | AR31: =IF(AND(AO31<=AP31, AP31<=AQ31), "ok", "nok") -> ok | AS31: =T31 -> 14.5 | AT31: =1.45*AQ31 -> 60.9 | AU31: =IF(AS31<=AT31, "ok", "nok") -> ok | AV31: Instalação Baixa Tensão (outros usos) | AW31: =IF(AV31="Instalação Media Tensão (iluminação)",6, IF(AV31="Instalação Media Tensão (outros usos)",8, IF(AV31="Instalação Baixa Tensão (iluminação)",3, IF(AV31="Instalação Baixa Tensão (outros usos)",5, IF(AV31="Instalação coletiva - coluna",1, IF(AV31="Instalação coletiva - entrada",0.5, IF(AV31="Entrada individual - portinhola",1.5))))))) -> 5 | AX31: =G31 -> 0.88 | AY31: =SQRT(1-AX31^2) -> 0.47497368 | AZ31: =IF(V31="Cu",0.0225, IF(V31="Al",0.036,0)) -> 0.0225 | BA31: 8e-05 | BB31: =IF(I31=400, (AZ31*(U31/AG31)*AX31+BA31*U31*AY31)*AO31, 2*(AZ31*(U31/AG31)*AX31+BA31*U31*AY31)*AO31) -> 0.73631811 | BC31: =(BB31/230)*100 -> 0.32013831 | BD31: =IF(BC31<AW31,"ok","nok") -> ok | BE31: =BC31+$BE$24 -> 3.3239445 | BF31: =IF(BE31<AW31,"ok","nok") -> ok
B32: QP-AP2 | D32: QE-A.P | F32: 2 | G32: 0.8 | H32: =F32/G32 -> 2.5 | I32: 400 | J32: =IF(I32 = 400,(H32*1000)/(SQRT(3)*400),(H32*1000)/(230)) -> 3.6084392 | K32: 1 | L32: 1 | M32: 1 | N32: =H32*K32*L32*M32 -> 2.5 | O32: =IF(I32=400,(N32*1000)/(SQRT(3)*400),(N32*1000)/230) -> 3.6084392 | P32: D | Q32: 6 | R32: 1 | S32: =Q32*R32 -> 6 | T32: =IF(P32 ="D",1.45*S32,IF(P32 ="DR",1.3*S32,IF(AND(P32="F",S32<=4),2.1*S32,IF(AND(P32="F",AND(S32>4,S32<=16)),1.9*S32,IF(AND(P32="F",S32>16),1.6*S32))))) -> 8.7 | U32: 48 | V32: Cu | W32: XLPE/EPR | X32: XV-5G4 | Y32: E | Z32: 13 | AA32: 52-C11 | AB32: 3 | AC32: 4 | AD32: 42 | AE32: 1 | AF32: 1 | AG32: =AC32*AE32 -> 4 | AH32: =AC32*AF32 -> 4 | AI32: =AD32*AE32 -> 42 | AJ32: 1 | AK32: 1 | AL32: 1 | AM32: 1 | AN32: =AI32*AJ32*AK32*AL32*AM32 -> 42 | AO32: =O32 -> 3.6084392 | AP32: =Q32 -> 6 | AQ32: =AN32 -> 42 | AR32: =IF(AND(AO32<=AP32, AP32<=AQ32), "ok", "nok") -> ok | AS32: =T32 -> 8.7 | AT32: =1.45*AQ32 -> 60.9 | AU32: =IF(AS32<=AT32, "ok", "nok") -> ok | AV32: Instalação Baixa Tensão (outros usos) | AW32: =IF(AV32="Instalação Media Tensão (iluminação)",6, IF(AV32="Instalação Media Tensão (outros usos)",8, IF(AV32="Instalação Baixa Tensão (iluminação)",3, IF(AV32="Instalação Baixa Tensão (outros usos)",5, IF(AV32="Instalação coletiva - coluna",1, IF(AV32="Instalação coletiva - entrada",0.5, IF(AV32="Entrada individual - portinhola",1.5))))))) -> 5 | AX32: =G32 -> 0.8 | AY32: =SQRT(1-AX32^2) -> 0.6 | AZ32: =IF(V32="Cu",0.0225, IF(V32="Al",0.036,0)) -> 0.0225 | BA32: 8e-05 | BB32: =IF(I32=400, (AZ32*(U32/AG32)*AX32+BA32*U32*AY32)*AO32, 2*(AZ32*(U32/AG32)*AX32+BA32*U32*AY32)*AO32) -> 0.78773671 | BC32: =(BB32/230)*100 -> 0.34249422 | BD32: =IF(BC32<AW32,"ok","nok") -> ok | BE32: =BC32+$BE$14 -> 2.3325882 | BF32: =IF(BE32<AW32,"ok","nok") -> ok
B33: QP-AP2 | D33: QE-A.M | F33: 2 | G33: 0.8 | H33: =F33/G33 -> 2.5 | I33: 400 | J33: =IF(I33 = 400,(H33*1000)/(SQRT(3)*400),(H33*1000)/(230)) -> 3.6084392 | K33: 1 | L33: 1 | M33: 1 | N33: =H33*K33*L33*M33 -> 2.5 | O33: =IF(I33=400,(N33*1000)/(SQRT(3)*400),(N33*1000)/230) -> 3.6084392 | P33: D | Q33: 6 | R33: 1 | S33: =Q33*R33 -> 6 | T33: =IF(P33 ="D",1.45*S33,IF(P33 ="DR",1.3*S33,IF(AND(P33="F",S33<=4),2.1*S33,IF(AND(P33="F",AND(S33>4,S33<=16)),1.9*S33,IF(AND(P33="F",S33>16),1.6*S33))))) -> 8.7 | U33: 7 | V33: Cu | W33: XLPE/EPR | X33: XV-5G4 | Y33: E | Z33: 13 | AA33: 52-C11 | AB33: 3 | AC33: 4 | AD33: 42 | AE33: 1 | AF33: 1 | AG33: =AC33*AE33 -> 4 | AH33: =AC33*AF33 -> 4 | AI33: =AD33*AE33 -> 42 | AJ33: 1 | AK33: 1 | AL33: 1 | AM33: 1 | AN33: =AI33*AJ33*AK33*AL33*AM33 -> 42 | AO33: =O33 -> 3.6084392 | AP33: =Q33 -> 6 | AQ33: =AN33 -> 42 | AR33: =IF(AND(AO33<=AP33, AP33<=AQ33), "ok", "nok") -> ok | AS33: =T33 -> 8.7 | AT33: =1.45*AQ33 -> 60.9 | AU33: =IF(AS33<=AT33, "ok", "nok") -> ok | AV33: Instalação Baixa Tensão (outros usos) | AW33: =IF(AV33="Instalação Media Tensão (iluminação)",6, IF(AV33="Instalação Media Tensão (outros usos)",8, IF(AV33="Instalação Baixa Tensão (iluminação)",3, IF(AV33="Instalação Baixa Tensão (outros usos)",5, IF(AV33="Instalação coletiva - coluna",1, IF(AV33="Instalação coletiva - entrada",0.5, IF(AV33="Entrada individual - portinhola",1.5))))))) -> 5 | AX33: =G33 -> 0.8 | AY33: =SQRT(1-AX33^2) -> 0.6 | AZ33: =IF(V33="Cu",0.0225, IF(V33="Al",0.036,0)) -> 0.0225 | BA33: 8e-05 | BB33: =IF(I33=400, (AZ33*(U33/AG33)*AX33+BA33*U33*AY33)*AO33, 2*(AZ33*(U33/AG33)*AX33+BA33*U33*AY33)*AO33) -> 0.11487827 | BC33: =(BB33/230)*100 -> 0.049947074 | BD33: =IF(BC33<AW33,"ok","nok") -> ok | BE33: =BC33+$BE$14 -> 2.040041 | BF33: =IF(BE33<AW33,"ok","nok") -> ok
B34: QP-AP2 | D34: QE-AP2 | F34: =H34*G34 -> 48.595145 | G34: 0.8 | H34: =H35+H36+H37+H38+H39 -> 60.743931 | I34: 400 | J34: =IF(I34 = 400,(H34*1000)/(SQRT(3)*400),(H34*1000)/(230)) -> 87.676313 | K34: 1 | L34: 0.8 | M34: 1 | N34: =H34*M34*L34*K34 -> 48.595145 | O34: =IF(I34=400,(N34*1000)/(SQRT(3)*400),(N34*1000)/230) -> 70.14105 | P34: D | Q34: 80 | R34: 1 | S34: =Q34*R34 -> 80 | T34: =IF(P34 ="D",1.45*S34,IF(P34 ="DR",1.3*S34,IF(AND(P34="F",S34<=4),2.1*S34,IF(AND(P34="F",AND(S34>4,S34<=16)),1.9*S34,IF(AND(P34="F",S34>16),1.6*S34))))) -> 116 | U34: 28 | V34: Cu | W34: XLPE/EPR | X34: XV-5G16 | Y34: E | Z34: 13 | AA34: 52-C11 | AB34: 3 | AC34: 16 | AD34: 100 | AE34: 1 | AF34: 1 | AG34: =AC34*AE34 -> 16 | AH34: =AC34*AF34 -> 16 | AI34: =AD34*AE34 -> 100 | AJ34: 1 | AK34: 1 | AL34: 1 | AM34: 1 | AN34: =AI34*AJ34*AK34*AL34*AM34 -> 100 | AO34: =O34 -> 70.14105 | AP34: =Q34 -> 80 | AQ34: =AN34 -> 100 | AR34: =IF(AND(AO34<=AP34, AP34<=AQ34), "ok", "nok") -> ok | AS34: =T34 -> 116 | AT34: =1.45*AQ34 -> 145 | AU34: =IF(AS34<=AT34, "ok", "nok") -> ok | AV34: Instalação Baixa Tensão (outros usos) | AW34: =IF(AV34="Instalação Media Tensão (iluminação)",6, IF(AV34="Instalação Media Tensão (outros usos)",8, IF(AV34="Instalação Baixa Tensão (iluminação)",3, IF(AV34="Instalação Baixa Tensão (outros usos)",5, IF(AV34="Instalação coletiva - coluna",1, IF(AV34="Instalação coletiva - entrada",0.5, IF(AV34="Entrada individual - portinhola",1.5))))))) -> 5 | AX34: =G34 -> 0.8 | AY34: =SQRT(1-AX34^2) -> 0.6 | AZ34: =IF(V34="Cu",0.0225, IF(V34="Al",0.036,0)) -> 0.0225 | BA34: 8e-05 | BB34: =IF(I34=400, (AZ34*(U34/AG34)*AX34+BA34*U34*AY34)*AO34, 2*(AZ34*(U34/AG34)*AX34+BA34*U34*AY34)*AO34) -> 2.3037126 | BC34: =(BB34/230)*100 -> 1.0016142 | BD34: =IF(BC34<AW34,"ok","nok") -> ok | BE34: =BC34+$BE$14 -> 2.9917082 | BF34: =IF(BE34<AW34,"ok","nok") -> ok
B35: QE-AP2 | D35: QE-M7 | F35: 2.2 | G35: 0.9 | H35: =F35/G35 -> 2.4444444 | I35: 400 | J35: =IF(I35 = 400,(H35*1000)/(SQRT(3)*400),(H35*1000)/(230)) -> 3.5282516 | K35: 1 | L35: 1 | M35: 1 | N35: =H35*K35*L35*M35 -> 2.4444444 | O35: =IF(I35=400,(N35*1000)/(SQRT(3)*400),(N35*1000)/230) -> 3.5282516 | P35: D | Q35: 6 | R35: 1 | S35: =Q35*R35 -> 6 | T35: =IF(P35 ="D",1.45*S35,IF(P35 ="DR",1.3*S35,IF(AND(P35="F",S35<=4),2.1*S35,IF(AND(P35="F",AND(S35>4,S35<=16)),1.9*S35,IF(AND(P35="F",S35>16),1.6*S35))))) -> 8.7 | U35: 10 | V35: Cu | W35: XLPE/EPR | X35: XV-5G4 | Y35: E | Z35: 13 | AA35: 52-C11 | AB35: 3 | AC35: 4 | AD35: 42 | AE35: 1 | AF35: 1 | AG35: =AC35*AE35 -> 4 | AH35: =AC35*AF35 -> 4 | AI35: =AD35*AE35 -> 42 | AJ35: 1 | AK35: 1 | AL35: 1 | AM35: 1 | AN35: =AI35*AJ35*AK35*AL35*AM35 -> 42 | AO35: =O35 -> 3.5282516 | AP35: =Q35 -> 6 | AQ35: =AN35 -> 42 | AR35: =IF(AND(AO35<=AP35, AP35<=AQ35), "ok", "nok") -> ok | AS35: =T35 -> 8.7 | AT35: =1.45*AQ35 -> 60.9 | AU35: =IF(AS35<=AT35, "ok", "nok") -> ok | AV35: Instalação Baixa Tensão (outros usos) | AW35: =IF(AV35="Instalação Media Tensão (iluminação)",6, IF(AV35="Instalação Media Tensão (outros usos)",8, IF(AV35="Instalação Baixa Tensão (iluminação)",3, IF(AV35="Instalação Baixa Tensão (outros usos)",5, IF(AV35="Instalação coletiva - coluna",1, IF(AV35="Instalação coletiva - entrada",0.5, IF(AV35="Entrada individual - portinhola",1.5))))))) -> 5 | AX35: =G35 -> 0.9 | AY35: =SQRT(1-AX35^2) -> 0.43588989 | AZ35: =IF(V35="Cu",0.0225, IF(V35="Al",0.036,0)) -> 0.0225 | BA35: 8e-05 | BB35: =IF(I35=400, (AZ35*(U35/AG35)*AX35+BA35*U35*AY35)*AO35, 2*(AZ35*(U35/AG35)*AX35+BA35*U35*AY35)*AO35) -> 0.17984808 | BC35: =(BB35/230)*100 -> 0.078194819 | BD35: =IF(BC35<AW35,"ok","nok") -> ok | BE35: =BC35+$BE$34 -> 3.069903 | BF35: =IF(BE35<AW35,"ok","nok") -> ok
B36: QE-AP2 | D36: QE-M8 | F36: 5.5 | G36: 0.88 | H36: =F36/G36 -> 6.25 | I36: 400 | J36: =IF(I36 = 400,(H36*1000)/(SQRT(3)*400),(H36*1000)/(230)) -> 9.021098 | K36: 1 | L36: 1 | M36: 1 | N36: =H36*K36*L36*M36 -> 6.25 | O36: =IF(I36=400,(N36*1000)/(SQRT(3)*400),(N36*1000)/230) -> 9.021098 | P36: D | Q36: 10 | R36: 1 | S36: =Q36*R36 -> 10 | T36: =IF(P36 ="D",1.45*S36,IF(P36 ="DR",1.3*S36,IF(AND(P36="F",S36<=4),2.1*S36,IF(AND(P36="F",AND(S36>4,S36<=16)),1.9*S36,IF(AND(P36="F",S36>16),1.6*S36))))) -> 14.5 | U36: 13 | V36: Cu | W36: XLPE/EPR | X36: XV-5G4 | Y36: E | Z36: 13 | AA36: 52-C11 | AB36: 3 | AC36: 4 | AD36: 42 | AE36: 1 | AF36: 1 | AG36: =AC36*AE36 -> 4 | AH36: =AC36*AF36 -> 4 | AI36: =AD36*AE36 -> 42 | AJ36: 1 | AK36: 1 | AL36: 1 | AM36: 1 | AN36: =AI36*AJ36*AK36*AL36*AM36 -> 42 | AO36: =O36 -> 9.021098 | AP36: =Q36 -> 10 | AQ36: =AN36 -> 42 | AR36: =IF(AND(AO36<=AP36, AP36<=AQ36), "ok", "nok") -> ok | AS36: =T36 -> 14.5 | AT36: =1.45*AQ36 -> 60.9 | AU36: =IF(AS36<=AT36, "ok", "nok") -> ok | AV36: Instalação Baixa Tensão (outros usos) | AW36: =IF(AV36="Instalação Media Tensão (iluminação)",6, IF(AV36="Instalação Media Tensão (outros usos)",8, IF(AV36="Instalação Baixa Tensão (iluminação)",3, IF(AV36="Instalação Baixa Tensão (outros usos)",5, IF(AV36="Instalação coletiva - coluna",1, IF(AV36="Instalação coletiva - entrada",0.5, IF(AV36="Entrada individual - portinhola",1.5))))))) -> 5 | AX36: =G36 -> 0.88 | AY36: =SQRT(1-AX36^2) -> 0.47497368 | AZ36: =IF(V36="Cu",0.0225, IF(V36="Al",0.036,0)) -> 0.0225 | BA36: 8e-05 | BB36: =IF(I36=400, (AZ36*(U36/AG36)*AX36+BA36*U36*AY36)*AO36, 2*(AZ36*(U36/AG36)*AX36+BA36*U36*AY36)*AO36) -> 0.58496383 | BC36: =(BB36/230)*100 -> 0.2543321 | BD36: =IF(BC36<AW36,"ok","nok") -> ok | BE36: =BC36+$BE$34 -> 3.2460403 | BF36: =IF(BE36<AW36,"ok","nok") -> ok
B37: QE-AP2 | D37: QE-M9 | F37: 4 | G37: 0.88 | H37: =F37/G37 -> 4.5454545 | I37: 400 | J37: =IF(I37 = 400,(H37*1000)/(SQRT(3)*400),(H37*1000)/(230)) -> 6.5607985 | K37: 1 | L37: 1 | M37: 1 | N37: =H37*K37*L37*M37 -> 4.5454545 | O37: =IF(I37=400,(N37*1000)/(SQRT(3)*400),(N37*1000)/230) -> 6.5607985 | P37: D | Q37: 10 | R37: 1 | S37: =Q37*R37 -> 10 | T37: =IF(P37 ="D",1.45*S37,IF(P37 ="DR",1.3*S37,IF(AND(P37="F",S37<=4),2.1*S37,IF(AND(P37="F",AND(S37>4,S37<=16)),1.9*S37,IF(AND(P37="F",S37>16),1.6*S37))))) -> 14.5 | U37: 25 | V37: Cu | W37: XLPE/EPR | X37: XV-5G4 | Y37: E | Z37: 13 | AA37: 52-C11 | AB37: 3 | AC37: 4 | AD37: 42 | AE37: 1 | AF37: 1 | AG37: =AC37*AE37 -> 4 | AH37: =AC37*AF37 -> 4 | AI37: =AD37*AE37 -> 42 | AJ37: 1 | AK37: 1 | AL37: 1 | AM37: 1 | AN37: =AI37*AJ37*AK37*AL37*AM37 -> 42 | AO37: =O37 -> 6.5607985 | AP37: =Q37 -> 10 | AQ37: =AN37 -> 42 | AR37: =IF(AND(AO37<=AP37, AP37<=AQ37), "ok", "nok") -> ok | AS37: =T37 -> 14.5 | AT37: =1.45*AQ37 -> 60.9 | AU37: =IF(AS37<=AT37, "ok", "nok") -> ok | AV37: Instalação Baixa Tensão (outros usos) | AW37: =IF(AV37="Instalação Media Tensão (iluminação)",6, IF(AV37="Instalação Media Tensão (outros usos)",8, IF(AV37="Instalação Baixa Tensão (iluminação)",3, IF(AV37="Instalação Baixa Tensão (outros usos)",5, IF(AV37="Instalação coletiva - coluna",1, IF(AV37="Instalação coletiva - entrada",0.5, IF(AV37="Entrada individual - portinhola",1.5))))))) -> 5 | AX37: =G37 -> 0.88 | AY37: =SQRT(1-AX37^2) -> 0.47497368 | AZ37: =IF(V37="Cu",0.0225, IF(V37="Al",0.036,0)) -> 0.0225 | BA37: 8e-05 | BB37: =IF(I37=400, (AZ37*(U37/AG37)*AX37+BA37*U37*AY37)*AO37, 2*(AZ37*(U37/AG37)*AX37+BA37*U37*AY37)*AO37) -> 0.81813123 | BC37: =(BB37/230)*100 -> 0.35570923 | BD37: =IF(BC37<AW37,"ok","nok") -> ok | BE37: =BC37+$BE$34 -> 3.3474174 | BF37: =IF(BE37<AW37,"ok","nok") -> ok
B38: QE-AP2 | D38: QE-M10 | F38: 15 | G38: 0.93 | H38: =F38/G38 -> 16.129032 | I38: 400 | J38: =IF(I38 = 400,(H38*1000)/(SQRT(3)*400),(H38*1000)/(230)) -> 23.280253 | K38: 1 | L38: 1 | M38: 1 | N38: =H38*K38*L38*M38 -> 16.129032 | O38: =IF(I38=400,(N38*1000)/(SQRT(3)*400),(N38*1000)/230) -> 23.280253 | P38: D | Q38: 25 | R38: 1 | S38: =Q38*R38 -> 25 | T38: =IF(P38 ="D",1.45*S38,IF(P38 ="DR",1.3*S38,IF(AND(P38="F",S38<=4),2.1*S38,IF(AND(P38="F",AND(S38>4,S38<=16)),1.9*S38,IF(AND(P38="F",S38>16),1.6*S38))))) -> 36.25 | U38: 32 | V38: Cu | W38: XLPE/EPR | X38: XV-5G4 | Y38: E | Z38: 13 | AA38: 52-C11 | AB38: 3 | AC38: 4 | AD38: 42 | AE38: 1 | AF38: 1 | AG38: =AC38*AE38 -> 4 | AH38: =AC38*AF38 -> 4 | AI38: =AD38*AE38 -> 42 | AJ38: 1 | AK38: 1 | AL38: 1 | AM38: 1 | AN38: =AI38*AJ38*AK38*AL38*AM38 -> 42 | AO38: =O38 -> 23.280253 | AP38: =Q38 -> 25 | AQ38: =AN38 -> 42 | AR38: =IF(AND(AO38<=AP38, AP38<=AQ38), "ok", "nok") -> ok | AS38: =T38 -> 36.25 | AT38: =1.45*AQ38 -> 60.9 | AU38: =IF(AS38<=AT38, "ok", "nok") -> ok | AV38: Instalação Baixa Tensão (outros usos) | AW38: =IF(AV38="Instalação Media Tensão (iluminação)",6, IF(AV38="Instalação Media Tensão (outros usos)",8, IF(AV38="Instalação Baixa Tensão (iluminação)",3, IF(AV38="Instalação Baixa Tensão (outros usos)",5, IF(AV38="Instalação coletiva - coluna",1, IF(AV38="Instalação coletiva - entrada",0.5, IF(AV38="Entrada individual - portinhola",1.5))))))) -> 5 | AX38: =G38 -> 0.93 | AY38: =SQRT(1-AX38^2) -> 0.36755952 | AZ38: =IF(V38="Cu",0.0225, IF(V38="Al",0.036,0)) -> 0.0225 | BA38: 8e-05 | BB38: =IF(I38=400, (AZ38*(U38/AG38)*AX38+BA38*U38*AY38)*AO38, 2*(AZ38*(U38/AG38)*AX38+BA38*U38*AY38)*AO38) -> 3.9190199 | BC38: =(BB38/230)*100 -> 1.7039217 | BD38: =IF(BC38<AW38,"ok","nok") -> ok | BE38: =BC38+$BE$34 -> 4.6956299 | BF38: =IF(BE38<AW38,"ok","nok") -> ok
B39: QE-AP2 | D39: QE-AVAC.2 | F39: 25.1 | G39: 0.8 | H39: =F39/G39 -> 31.375 | I39: 400 | J39: =IF(I39 = 400,(H39*1000)/(SQRT(3)*400),(H39*1000)/(230)) -> 45.285912 | K39: 1 | L39: 1 | M39: 1 | N39: =H39*K39*L39*M39 -> 31.375 | O39: =IF(I39=400,(N39*1000)/(SQRT(3)*400),(N39*1000)/230) -> 45.285912 | P39: D | Q39: 50 | R39: 1 | S39: =Q39*R39 -> 50 | T39: =IF(P39 ="D",1.45*S39,IF(P39 ="DR",1.3*S39,IF(AND(P39="F",S39<=4),2.1*S39,IF(AND(P39="F",AND(S39>4,S39<=16)),1.9*S39,IF(AND(P39="F",S39>16),1.6*S39))))) -> 72.5 | U39: 8.5 | V39: Cu | W39: XLPE/EPR | X39: XV-5G6 | Y39: E | Z39: 13 | AA39: 52-C11 | AB39: 3 | AC39: 6 | AD39: 54 | AE39: 1 | AF39: 1 | AG39: =AC39*AE39 -> 6 | AH39: =AC39*AF39 -> 6 | AI39: =AD39*AE39 -> 54 | AJ39: 1 | AK39: 1 | AL39: 1 | AM39: 1 | AN39: =AI39*AJ39*AK39*AL39*AM39 -> 54 | AO39: =O39 -> 45.285912 | AP39: =Q39 -> 50 | AQ39: =AN39 -> 54 | AR39: =IF(AND(AO39<=AP39, AP39<=AQ39), "ok", "nok") -> ok | AS39: =T39 -> 72.5 | AT39: =1.45*AQ39 -> 78.3 | AU39: =IF(AS39<=AT39, "ok", "nok") -> ok | AV39: Instalação Baixa Tensão (outros usos) | AW39: =IF(AV39="Instalação Media Tensão (iluminação)",6, IF(AV39="Instalação Media Tensão (outros usos)",8, IF(AV39="Instalação Baixa Tensão (iluminação)",3, IF(AV39="Instalação Baixa Tensão (outros usos)",5, IF(AV39="Instalação coletiva - coluna",1, IF(AV39="Instalação coletiva - entrada",0.5, IF(AV39="Entrada individual - portinhola",1.5))))))) -> 5 | AX39: =G39 -> 0.8 | AY39: =SQRT(1-AX39^2) -> 0.6 | AZ39: =IF(V39="Cu",0.0225, IF(V39="Al",0.036,0)) -> 0.0225 | BA39: 8e-05 | BB39: =IF(I39=400, (AZ39*(U39/AG39)*AX39+BA39*U39*AY39)*AO39, 2*(AZ39*(U39/AG39)*AX39+BA39*U39*AY39)*AO39) -> 1.1732674 | BC39: =(BB39/230)*100 -> 0.51011626 | BD39: =IF(BC39<AW39,"ok","nok") -> ok | BE39: =BC39+$BE$34 -> 3.5018244 | BF39: =IF(BE39<AW39,"ok","nok") -> ok
B40: QP-CD | D40: QE-CD | F40: 6.5 | G40: 0.8 | H40: =F40/G40 -> 8.125 | I40: 400 | J40: =IF(I40 = 400,(H40*1000)/(SQRT(3)*400),(H40*1000)/(230)) -> 11.727427 | K40: 1 | L40: 1 | M40: 1 | N40: =H40*K40*L40*M40 -> 8.125 | O40: =IF(I40=400,(N40*1000)/(SQRT(3)*400),(N40*1000)/230) -> 11.727427 | P40: D | Q40: 16 | R40: 1 | S40: =Q40*R40 -> 16 | T40: =IF(P40 ="D",1.45*S40,IF(P40 ="DR",1.3*S40,IF(AND(P40="F",S40<=4),2.1*S40,IF(AND(P40="F",AND(S40>4,S40<=16)),1.9*S40,IF(AND(P40="F",S40>16),1.6*S40))))) -> 23.2 | U40: 9 | V40: Cu | W40: XLPE/EPR | X40: XV-5G4 | Y40: E | Z40: 13 | AA40: 52-C11 | AB40: 3 | AC40: 4 | AD40: 42 | AE40: 1 | AF40: 1 | AG40: =AC40*AE40 -> 4 | AH40: =AC40*AF40 -> 4 | AI40: =AD40*AE40 -> 42 | AJ40: 1 | AK40: 1 | AL40: 1 | AM40: 1 | AN40: =AI40*AJ40*AK40*AL40*AM40 -> 42 | AO40: =O40 -> 11.727427 | AP40: =Q40 -> 16 | AQ40: =AN40 -> 42 | AR40: =IF(AND(AO40<=AP40, AP40<=AQ40), "ok", "nok") -> ok | AS40: =T40 -> 23.2 | AT40: =1.45*AQ40 -> 60.9 | AU40: =IF(AS40<=AT40, "ok", "nok") -> ok | AV40: Instalação Baixa Tensão (outros usos) | AW40: =IF(AV40="Instalação Media Tensão (iluminação)",6, IF(AV40="Instalação Media Tensão (outros usos)",8, IF(AV40="Instalação Baixa Tensão (iluminação)",3, IF(AV40="Instalação Baixa Tensão (outros usos)",5, IF(AV40="Instalação coletiva - coluna",1, IF(AV40="Instalação coletiva - entrada",0.5, IF(AV40="Entrada individual - portinhola",1.5))))))) -> 5 | AX40: =G40 -> 0.8 | AY40: =SQRT(1-AX40^2) -> 0.6 | AZ40: =IF(V40="Cu",0.0225, IF(V40="Al",0.036,0)) -> 0.0225 | BA40: 8e-05 | BB40: =IF(I40=400, (AZ40*(U40/AG40)*AX40+BA40*U40*AY40)*AO40, 2*(AZ40*(U40/AG40)*AX40+BA40*U40*AY40)*AO40) -> 0.48002706 | BC40: =(BB40/230)*100 -> 0.20870742 | BD40: =IF(BC40<AW40,"ok","nok") -> ok | BE40: =BC40+$BE$15 -> 1.4400929 | BF40: =IF(BE40<AW40,"ok","nok") -> ok
